Workbook

Sheet Summary
A1: Fast Follower Analysis – Executive Summary
A3: APPLICATION UNIVERSE
A4: Metric | B4: Count | C4: Notes
A5: Total Business Apps (Risk File) | B5: =COUNTA(All_Risk_Apps!A:A)-1 -> 2 | C5: Full app inventory
A6: Apps Active in Illumio (bus_active=TRUE) | B6: =COUNTIF(All_Risk_Apps!C:C,TRUE()) -> 0
A7: FUSE Members | B7: =COUNTIF(All_Risk_Apps!I:I,"Yes") -> 0
A8: FND-17108 Finding Apps | B8: =COUNTIF(All_Risk_Apps!K:K,"Yes") -> 0
A10: RISK RATING BREAKDOWN
A11: Risk Rating | B11: Total Apps | C11: FUSE Members | D11: Finding Apps | E11: Fast Follower Eligible
A12: Very High | B12: =COUNTIF(All_Risk_Apps!D:D,"Very High") -> 0 | C12: =COUNTIFS(All_Risk_Apps!D:D,"Very High",All_Risk_Apps!I:I,"Yes") -> 0 | D12: =COUNTIFS(All_Risk_Apps!D:D,"Very High",All_Risk_Apps!K:K,"Yes") -> 0 | E12: N/A – See Bucket 1
A13: High | B13: =COUNTIF(All_Risk_Apps!D:D,"High") -> 0 | C13: =COUNTIFS(All_Risk_Apps!D:D,"High",All_Risk_Apps!I:I,"Yes") -> 0 | D13: =COUNTIFS(All_Risk_Apps!D:D,"High",All_Risk_Apps!K:K,"Yes") -> 0 | E13: N/A – See Bucket 1
A14: Moderate | B14: =COUNTIF(All_Risk_Apps!D:D,"Moderate") -> 0 | C14: =COUNTIFS(All_Risk_Apps!D:D,"Moderate",All_Risk_Apps!I:I,"Yes") -> 0 | D14: =COUNTIFS(All_Risk_Apps!D:D,"Moderate",All_Risk_Apps!K:K,"Yes") -> 0 | E14: =COUNTIFS(All_Risk_Apps!D:D,"Moderate",All_Risk_Apps!J:J,"Fast Follower") -> 0
A15: Low | B15: =COUNTIF(All_Risk_Apps!D:D,"Low") -> 0 | C15: =COUNTIFS(All_Risk_Apps!D:D,"Low",All_Risk_Apps!I:I,"Yes") -> 0 | D15: =COUNTIFS(All_Risk_Apps!D:D,"Low",All_Risk_Apps!K:K,"Yes") -> 0 | E15: =COUNTIFS(All_Risk_Apps!D:D,"Low",All_Risk_Apps!J:J,"Fast Follower") -> 0
A17: FAST FOLLOWER BUCKETS
A18: Bucket | B18: Description | C18: App Count | D18: Server Workloads | E18: Container Workloads
A19: Bucket 1 | B19: High/Very High Risk – NOT in FND-17108 Findings | C19: =COUNTA(Bucket1_High_Risk!A:A)-1 -> 202 | D19: =SUMIF(Bucket1_High_Risk!A:A,"<>",Bucket1_High_Risk!M:M) -> 0 | E19: =SUMIF(Bucket1_High_Risk!A:A,"<>",Bucket1_High_Risk!N:N) -> 0
A20: Bucket 2 | B20: Fast Followers – Low/Moderate, FUSE Member, NOT a Finding | C20: =COUNTA(Bucket2_Fast_Followers!A:A)-1 -> 202 | D20: =SUMIF(Bucket2_Fast_Followers!A:A,"<>",Bucket2_Fast_Followers!M:M) -> 0 | E20: =SUMIF(Bucket2_Fast_Followers!A:A,"<>",Bucket2_Fast_Followers!N:N) -> 0

Sheet All_Risk_Apps
A1: All Business Applications – Risk & Classification
A2: rsk_u_application | B2: bus_correlation_id | C2: bus_active | D2: rsk_u_overall_risk_rating | E2: bus_application_manager | F2: bus_application_type | G2: rsk_u_segment_it_risk_manager | H2: dep_u_segment_risk_officer | I2: FUSE_Member | J2: Fast_Follower_Status | K2: FND_Finding
A3: ⬇ PASTE your s_business_app_to_risk data starting in row 4 (columns A–H). Columns I, J, K are auto-calculated.
I4: =IF(B4="","",IF(COUNTIF(FUSE_CI!$A:$A,B4)>0,"Yes","No")) | J4: =IF(B4="","",IF(AND(D4<>"High",D4<>"Very High",I4="Yes",K4="No"),"Fast Follower","Not Eligible")) | K4: =IF(B4="","",IF(COUNTIF(Finding_List!$A:$A,B4)>0,"Yes","No"))
I5: =IF(B5="","",IF(COUNTIF(FUSE_CI!$A:$A,B5)>0,"Yes","No")) | J5: =IF(B5="","",IF(AND(D5<>"High",D5<>"Very High",I5="Yes",K5="No"),"Fast Follower","Not Eligible")) | K5: =IF(B5="","",IF(COUNTIF(Finding_List!$A:$A,B5)>0,"Yes","No"))
I6: =IF(B6="","",IF(COUNTIF(FUSE_CI!$A:$A,B6)>0,"Yes","No")) | J6: =IF(B6="","",IF(AND(D6<>"High",D6<>"Very High",I6="Yes",K6="No"),"Fast Follower","Not Eligible")) | K6: =IF(B6="","",IF(COUNTIF(Finding_List!$A:$A,B6)>0,"Yes","No"))
I7: =IF(B7="","",IF(COUNTIF(FUSE_CI!$A:$A,B7)>0,"Yes","No")) | J7: =IF(B7="","",IF(AND(D7<>"High",D7<>"Very High",I7="Yes",K7="No"),"Fast Follower","Not Eligible")) | K7: =IF(B7="","",IF(COUNTIF(Finding_List!$A:$A,B7)>0,"Yes","No"))
I8: =IF(B8="","",IF(COUNTIF(FUSE_CI!$A:$A,B8)>0,"Yes","No")) | J8: =IF(B8="","",IF(AND(D8<>"High",D8<>"Very High",I8="Yes",K8="No"),"Fast Follower","Not Eligible")) | K8: =IF(B8="","",IF(COUNTIF(Finding_List!$A:$A,B8)>0,"Yes","No"))
I9: =IF(B9="","",IF(COUNTIF(FUSE_CI!$A:$A,B9)>0,"Yes","No")) | J9: =IF(B9="","",IF(AND(D9<>"High",D9<>"Very High",I9="Yes",K9="No"),"Fast Follower","Not Eligible")) | K9: =IF(B9="","",IF(COUNTIF(Finding_List!$A:$A,B9)>0,"Yes","No"))
I10: =IF(B10="","",IF(COUNTIF(FUSE_CI!$A:$A,B10)>0,"Yes","No")) | J10: =IF(B10="","",IF(AND(D10<>"High",D10<>"Very High",I10="Yes",K10="No"),"Fast Follower","Not Eligible")) | K10: =IF(B10="","",IF(COUNTIF(Finding_List!$A:$A,B10)>0,"Yes","No"))
I11: =IF(B11="","",IF(COUNTIF(FUSE_CI!$A:$A,B11)>0,"Yes","No")) | J11: =IF(B11="","",IF(AND(D11<>"High",D11<>"Very High",I11="Yes",K11="No"),"Fast Follower","Not Eligible")) | K11: =IF(B11="","",IF(COUNTIF(Finding_List!$A:$A,B11)>0,"Yes","No"))
I12: =IF(B12="","",IF(COUNTIF(FUSE_CI!$A:$A,B12)>0,"Yes","No")) | J12: =IF(B12="","",IF(AND(D12<>"High",D12<>"Very High",I12="Yes",K12="No"),"Fast Follower","Not Eligible")) | K12: =IF(B12="","",IF(COUNTIF(Finding_List!$A:$A,B12)>0,"Yes","No"))
I13: =IF(B13="","",IF(COUNTIF(FUSE_CI!$A:$A,B13)>0,"Yes","No")) | J13: =IF(B13="","",IF(AND(D13<>"High",D13<>"Very High",I13="Yes",K13="No"),"Fast Follower","Not Eligible")) | K13: =IF(B13="","",IF(COUNTIF(Finding_List!$A:$A,B13)>0,"Yes","No"))
I14: =IF(B14="","",IF(COUNTIF(FUSE_CI!$A:$A,B14)>0,"Yes","No")) | J14: =IF(B14="","",IF(AND(D14<>"High",D14<>"Very High",I14="Yes",K14="No"),"Fast Follower","Not Eligible")) | K14: =IF(B14="","",IF(COUNTIF(Finding_List!$A:$A,B14)>0,"Yes","No"))
I15: =IF(B15="","",IF(COUNTIF(FUSE_CI!$A:$A,B15)>0,"Yes","No")) | J15: =IF(B15="","",IF(AND(D15<>"High",D15<>"Very High",I15="Yes",K15="No"),"Fast Follower","Not Eligible")) | K15: =IF(B15="","",IF(COUNTIF(Finding_List!$A:$A,B15)>0,"Yes","No"))
... I1233: =IF(B1233="","",IF(COUNTIF(FUSE_CI!$A:$A,B1233)>0,"Yes","No")) | J1233: =IF(B1233="","",IF(AND(D1233<>"High",D1233<>"Very High",I1233="Yes",K1233="No"),"Fast Follower","Not Eligible")) | K1233: =IF(B1233="","",IF(COUNTIF(Finding_List!$A:$A,B1233)>0,"Yes","No"))

Sheet Bucket1_High_Risk
A1: BUCKET 1 – High / Very High Risk Apps NOT in FND-17108 Findings
A2: App Name | B2: CI (bus_correlation_id) | C2: Risk Rating | D2: Bus Active | E2: App Manager | F2: App Type | G2: FUSE Member | H2: Server Enforcement Mode | I2: Server Online Status | J2: Retired Servers (R-RETIRED_IN_CMDB) | K2: Container Enforcement Mode | L2: Finding App? | M2: Server Count | N2: Container Count
A3: ⬇ These rows auto-populate from All_Risk_Apps where Risk = High or Very High AND FND_Finding = No. Paste source data in All_Risk_Apps, Server_Inventory, and Container_Inventory tabs first.
A4: =IFERROR(INDEX(All_Risk_Apps!$A$4:$A$1233,_xludf.aggregate(15,6,(ROW(All_Risk_Apps!$A$4:$A$1233)-ROW(All_Risk_Apps!$A$4)+1)/((OR(All_Risk_Apps!$D$4:$D$1233={"High","Very High"}))*(All_Risk_Apps!$K$4:$K$1233="No")*(All_Risk_Apps!$A$4:$A$1233<>"")),1)),"") | B4: =IFERROR(INDEX(All_Risk_Apps!$B$4:$B$1233,_xludf.aggregate(15,6,(ROW(All_Risk_Apps!$A$4:$A$1233)-ROW(All_Risk_Apps!$A$4)+1)/((OR(All_Risk_Apps!$D$4:$D$1233={"High","Very High"}))*(All_Risk_Apps!$K$4:$K$1233="No")*(All_Risk_Apps!$A$4:$A$1233<>"")),1)),"") | C4: =IFERROR(INDEX(All_Risk_Apps!$D$4:$D$1233,_xludf.aggregate(15,6,(ROW(All_Risk_Apps!$A$4:$A$1233)-ROW(All_Risk_Apps!$A$4)+1)/((OR(All_Risk_Apps!$D$4:$D$1233={"High","Very High"}))*(All_Risk_Apps!$K$4:$K$1233="No")*(All_Risk_Apps!$A$4:$A$1233<>"")),1)),"") | D4: =IFERROR(INDEX(All_Risk_Apps!$C$4:$C$1233,_xludf.aggregate(15,6,(ROW(All_Risk_Apps!$A$4:$A$1233)-ROW(All_Risk_Apps!$A$4)+1)/((OR(All_Risk_Apps!$D$4:$D$1233={"High","Very High"}))*(All_Risk_Apps!$K$4:$K$1233="No")*(All_Risk_Apps!$A$4:$A$1233<>"")),1)),"") | E4: =IFERROR(INDEX(All_Risk_Apps!$E$4:$E$1233,_xludf.aggregate(15,6,(ROW(All_Risk_Apps!$A$4:$A$1233)-ROW(All_Risk_Apps!$A$4)+1)/((OR(All_Risk_Apps!$D$4:$D$1233={"High","Very High"}))*(All_Risk_Apps!$K$4:$K$1233="No")*(All_Risk_Apps!$A$4:$A$1233<>"")),1)),"") | F4: =IFERROR(INDEX(All_Risk_Apps!$F$4:$F$1233,_xludf.aggregate(15,6,(ROW(All_Risk_Apps!$A$4:$A$1233)-ROW(All_Risk_Apps!$A$4)+1)/((OR(All_Risk_Apps!$D$4:$D$1233={"High","Very High"}))*(All_Risk_Apps!$K$4:$K$1233="No")*(All_Risk_Apps!$A$4:$A$1233<>"")),1)),"") | G4: =IFERROR(INDEX(All_Risk_Apps!$I$4:$I$1233,_xludf.aggregate(15,6,(ROW(All_Risk_Apps!$A$4:$A$1233)-ROW(All_Risk_Apps!$A$4)+1)/((OR(All_Risk_Apps!$D$4:$D$1233={"High","Very High"}))*(All_Risk_Apps!$K$4:$K$1233="No")*(All_Risk_Apps!$A$4:$A$1233<>"")),1)),"") | H4: =IF(B4="","",IFERROR(INDEX(Server_Inventory!$R:$R,MATCH(B4,Server_Inventory!$Z:$Z,0)),"Not Found")) | I4: =IF(B4="","",IFERROR(INDEX(Server_Inventory!$S:$S,MATCH(B4,Server_Inventory!$Z:$Z,0)),"Not Found")) | J4: =IF(B4="","",COUNTIFS(Server_Inventory!$Z:$Z,B4,Server_Inventory!$P:$P,"R-RETIRED_IN_CMDB")) | K4: =IF(B4="","",IFERROR(INDEX(Container_Inventory!$F:$F,MATCH(B4,Container_Inventory!$L:$L,0)),"Not Found")) | L4: =IF(B4="","",IF(COUNTIF(Finding_List!$A:$A,B4)>0,"Yes","No")) | M4: =IF(B4="","",COUNTIF(Server_Inventory!$Z:$Z,B4)) | N4: =IF(B4="","",COUNTIF(Container_Inventory!$L:$L,B4))
A5: =IFERROR(INDEX(All_Risk_Apps!$A$4:$A$1233,_xludf.aggregate(15,6,(ROW(All_Risk_Apps!$A$4:$A$1233)-ROW(All_Risk_Apps!$A$4)+1)/((OR(All_Risk_Apps!$D$4:$D$1233={"High","Very High"}))*(All_Risk_Apps!$K$4:$K$1233="No")*(All_Risk_Apps!$A$4:$A$1233<>"")),2)),"") | B5: =IFERROR(INDEX(All_Risk_Apps!$B$4:$B$1233,_xludf.aggregate(15,6,(ROW(All_Risk_Apps!$A$4:$A$1233)-ROW(All_Risk_Apps!$A$4)+1)/((OR(All_Risk_Apps!$D$4:$D$1233={"High","Very High"}))*(All_Risk_Apps!$K$4:$K$1233="No")*(All_Risk_Apps!$A$4:$A$1233<>"")),2)),"") | C5: =IFERROR(INDEX(All_Risk_Apps!$D$4:$D$1233,_xludf.aggregate(15,6,(ROW(All_Risk_Apps!$A$4:$A$1233)-ROW(All_Risk_Apps!$A$4)+1)/((OR(All_Risk_Apps!$D$4:$D$1233={"High","Very High"}))*(All_Risk_Apps!$K$4:$K$1233="No")*(All_Risk_Apps!$A$4:$A$1233<>"")),2)),"") | D5: =IFERROR(INDEX(All_Risk_Apps!$C$4:$C$1233,_xludf.aggregate(15,6,(ROW(All_Risk_Apps!$A$4:$A$1233)-ROW(All_Risk_Apps!$A$4)+1)/((OR(All_Risk_Apps!$D$4:$D$1233={"High","Very High"}))*(All_Risk_Apps!$K$4:$K$1233="No")*(All_Risk_Apps!$A$4:$A$1233<>"")),2)),"") | E5: =IFERROR(INDEX(All_Risk_Apps!$E$4:$E$1233,_xludf.aggregate(15,6,(ROW(All_Risk_Apps!$A$4:$A$1233)-ROW(All_Risk_Apps!$A$4)+1)/((OR(All_Risk_Apps!$D$4:$D$1233={"High","Very High"}))*(All_Risk_Apps!$K$4:$K$1233="No")*(All_Risk_Apps!$A$4:$A$1233<>"")),2)),"") | F5: =IFERROR(INDEX(All_Risk_Apps!$F$4:$F$1233,_xludf.aggregate(15,6,(ROW(All_Risk_Apps!$A$4:$A$1233)-ROW(All_Risk_Apps!$A$4)+1)/((OR(All_Risk_Apps!$D$4:$D$1233={"High","Very High"}))*(All_Risk_Apps!$K$4:$K$1233="No")*(All_Risk_Apps!$A$4:$A$1233<>"")),2)),"") | G5: =IFERROR(INDEX(All_Risk_Apps!$I$4:$I$1233,_xludf.aggregate(15,6,(ROW(All_Risk_Apps!$A$4:$A$1233)-ROW(All_Risk_Apps!$A$4)+1)/((OR(All_Risk_Apps!$D$4:$D$1233={"High","Very High"}))*(All_Risk_Apps!$K$4:$K$1233="No")*(All_Risk_Apps!$A$4:$A$1233<>"")),2)),"") | H5: =IF(B5="","",IFERROR(INDEX(Server_Inventory!$R:$R,MATCH(B5,Server_Inventory!$Z:$Z,0)),"Not Found")) | I5: =IF(B5="","",IFERROR(INDEX(Server_Inventory!$S:$S,MATCH(B5,Server_Inventory!$Z:$Z,0)),"Not Found")) | J5: =IF(B5="","",COUNTIFS(Server_Inventory!$Z:$Z,B5,Server_Inventory!$P:$P,"R-RETIRED_IN_CMDB")) | K5: =IF(B5="","",IFERROR(INDEX(Container_Inventory!$F:$F,MATCH(B5,Container_Inventory!$L:$L,0)),"Not Found")) | L5: =IF(B5="","",IF(COUNTIF(Finding_List!$A:$A,B5)>0,"Yes","No")) | M5: =IF(B5="","",COUNTIF(Server_Inventory!$Z:$Z,B5)) | N5: =IF(B5="","",COUNTIF(Container_Inventory!$L:$L,B5))
A6: =IFERROR(INDEX(All_Risk_Apps!$A$4:$A$1233,_xludf.aggregate(15,6,(ROW(All_Risk_Apps!$A$4:$A$1233)-ROW(All_Risk_Apps!$A$4)+1)/((OR(All_Risk_Apps!$D$4:$D$1233={"High","Very High"}))*(All_Risk_Apps!$K$4:$K$1233="No")*(All_Risk_Apps!$A$4:$A$1233<>"")),3)),"") | B6: =IFERROR(INDEX(All_Risk_Apps!$B$4:$B$1233,_xludf.aggregate(15,6,(ROW(All_Risk_Apps!$A$4:$A$1233)-ROW(All_Risk_Apps!$A$4)+1)/((OR(All_Risk_Apps!$D$4:$D$1233={"High","Very High"}))*(All_Risk_Apps!$K$4:$K$1233="No")*(All_Risk_Apps!$A$4:$A$1233<>"")),3)),"") | C6: =IFERROR(INDEX(All_Risk_Apps!$D$4:$D$1233,_xludf.aggregate(15,6,(ROW(All_Risk_Apps!$A$4:$A$1233)-ROW(All_Risk_Apps!$A$4)+1)/((OR(All_Risk_Apps!$D$4:$D$1233={"High","Very High"}))*(All_Risk_Apps!$K$4:$K$1233="No")*(All_Risk_Apps!$A$4:$A$1233<>"")),3)),"") | D6: =IFERROR(INDEX(All_Risk_Apps!$C$4:$C$1233,_xludf.aggregate(15,6,(ROW(All_Risk_Apps!$A$4:$A$1233)-ROW(All_Risk_Apps!$A$4)+1)/((OR(All_Risk_Apps!$D$4:$D$1233={"High","Very High"}))*(All_Risk_Apps!$K$4:$K$1233="No")*(All_Risk_Apps!$A$4:$A$1233<>"")),3)),"") | E6: =IFERROR(INDEX(All_Risk_Apps!$E$4:$E$1233,_xludf.aggregate(15,6,(ROW(All_Risk_Apps!$A$4:$A$1233)-ROW(All_Risk_Apps!$A$4)+1)/((OR(All_Risk_Apps!$D$4:$D$1233={"High","Very High"}))*(All_Risk_Apps!$K$4:$K$1233="No")*(All_Risk_Apps!$A$4:$A$1233<>"")),3)),"") | F6: =IFERROR(INDEX(All_Risk_Apps!$F$4:$F$1233,_xludf.aggregate(15,6,(ROW(All_Risk_Apps!$A$4:$A$1233)-ROW(All_Risk_Apps!$A$4)+1)/((OR(All_Risk_Apps!$D$4:$D$1233={"High","Very High"}))*(All_Risk_Apps!$K$4:$K$1233="No")*(All_Risk_Apps!$A$4:$A$1233<>"")),3)),"") | G6: =IFERROR(INDEX(All_Risk_Apps!$I$4:$I$1233,_xludf.aggregate(15,6,(ROW(All_Risk_Apps!$A$4:$A$1233)-ROW(All_Risk_Apps!$A$4)+1)/((OR(All_Risk_Apps!$D$4:$D$1233={"High","Very High"}))*(All_Risk_Apps!$K$4:$K$1233="No")*(All_Risk_Apps!$A$4:$A$1233<>"")),3)),"") | H6: =IF(B6="","",IFERROR(INDEX(Server_Inventory!$R:$R,MATCH(B6,Server_Inventory!$Z:$Z,0)),"Not Found")) | I6: =IF(B6="","",IFERROR(INDEX(Server_Inventory!$S:$S,MATCH(B6,Server_Inventory!$Z:$Z,0)),"Not Found")) | J6: =IF(B6="","",COUNTIFS(Server_Inventory!$Z:$Z,B6,Server_Inventory!$P:$P,"R-RETIRED_IN_CMDB")) | K6: =IF(B6="","",IFERROR(INDEX(Container_Inventory!$F:$F,MATCH(B6,Container_Inventory!$L:$L,0)),"Not Found")) | L6: =IF(B6="","",IF(COUNTIF(Finding_List!$A:$A,B6)>0,"Yes","No")) | M6: =IF(B6="","",COUNTIF(Server_Inventory!$Z:$Z,B6)) | N6: =IF(B6="","",COUNTIF(Container_Inventory!$L:$L,B6))
A7: =IFERROR(INDEX(All_Risk_Apps!$A$4:$A$1233,_xludf.aggregate(15,6,(ROW(All_Risk_Apps!$A$4:$A$1233)-ROW(All_Risk_Apps!$A$4)+1)/((OR(All_Risk_Apps!$D$4:$D$1233={"High","Very High"}))*(All_Risk_Apps!$K$4:$K$1233="No")*(All_Risk_Apps!$A$4:$A$1233<>"")),4)),"") | B7: =IFERROR(INDEX(All_Risk_Apps!$B$4:$B$1233,_xludf.aggregate(15,6,(ROW(All_Risk_Apps!$A$4:$A$1233)-ROW(All_Risk_Apps!$A$4)+1)/((OR(All_Risk_Apps!$D$4:$D$1233={"High","Very High"}))*(All_Risk_Apps!$K$4:$K$1233="No")*(All_Risk_Apps!$A$4:$A$1233<>"")),4)),"") | C7: =IFERROR(INDEX(All_Risk_Apps!$D$4:$D$1233,_xludf.aggregate(15,6,(ROW(All_Risk_Apps!$A$4:$A$1233)-ROW(All_Risk_Apps!$A$4)+1)/((OR(All_Risk_Apps!$D$4:$D$1233={"High","Very High"}))*(All_Risk_Apps!$K$4:$K$1233="No")*(All_Risk_Apps!$A$4:$A$1233<>"")),4)),"") | D7: =IFERROR(INDEX(All_Risk_Apps!$C$4:$C$1233,_xludf.aggregate(15,6,(ROW(All_Risk_Apps!$A$4:$A$1233)-ROW(All_Risk_Apps!$A$4)+1)/((OR(All_Risk_Apps!$D$4:$D$1233={"High","Very High"}))*(All_Risk_Apps!$K$4:$K$1233="No")*(All_Risk_Apps!$A$4:$A$1233<>"")),4)),"") | E7: =IFERROR(INDEX(All_Risk_Apps!$E$4:$E$1233,_xludf.aggregate(15,6,(ROW(All_Risk_Apps!$A$4:$A$1233)-ROW(All_Risk_Apps!$A$4)+1)/((OR(All_Risk_Apps!$D$4:$D$1233={"High","Very High"}))*(All_Risk_Apps!$K$4:$K$1233="No")*(All_Risk_Apps!$A$4:$A$1233<>"")),4)),"") | F7: =IFERROR(INDEX(All_Risk_Apps!$F$4:$F$1233,_xludf.aggregate(15,6,(ROW(All_Risk_Apps!$A$4:$A$1233)-ROW(All_Risk_Apps!$A$4)+1)/((OR(All_Risk_Apps!$D$4:$D$1233={"High","Very High"}))*(All_Risk_Apps!$K$4:$K$1233="No")*(All_Risk_Apps!$A$4:$A$1233<>"")),4)),"") | G7: =IFERROR(INDEX(All_Risk_Apps!$I$4:$I$1233,_xludf.aggregate(15,6,(ROW(All_Risk_Apps!$A$4:$A$1233)-ROW(All_Risk_Apps!$A$4)+1)/((OR(All_Risk_Apps!$D$4:$D$1233={"High","Very High"}))*(All_Risk_Apps!$K$4:$K$1233="No")*(All_Risk_Apps!$A$4:$A$1233<>"")),4)),"") | H7: =IF(B7="","",IFERROR(INDEX(Server_Inventory!$R:$R,MATCH(B7,Server_Inventory!$Z:$Z,0)),"Not Found")) | I7: =IF(B7="","",IFERROR(INDEX(Server_Inventory!$S:$S,MATCH(B7,Server_Inventory!$Z:$Z,0)),"Not Found")) | J7: =IF(B7="","",COUNTIFS(Server_Inventory!$Z:$Z,B7,Server_Inventory!$P:$P,"R-RETIRED_IN_CMDB")) | K7: =IF(B7="","",IFERROR(INDEX(Container_Inventory!$F:$F,MATCH(B7,Container_Inventory!$L:$L,0)),"Not Found")) | L7: =IF(B7="","",IF(COUNTIF(Finding_List!$A:$A,B7)>0,"Yes","No")) | M7: =IF(B7="","",COUNTIF(Server_Inventory!$Z:$Z,B7)) | N7: =IF(B7="","",COUNTIF(Container_Inventory!$L:$L,B7))
A8: =IFERROR(INDEX(All_Risk_Apps!$A$4:$A$1233,_xludf.aggregate(15,6,(ROW(All_Risk_Apps!$A$4:$A$1233)-ROW(All_Risk_Apps!$A$4)+1)/((OR(All_Risk_Apps!$D$4:$D$1233={"High","Very High"}))*(All_Risk_Apps!$K$4:$K$1233="No")*(All_Risk_Apps!$A$4:$A$1233<>"")),5)),"") | B8: =IFERROR(INDEX(All_Risk_Apps!$B$4:$B$1233,_xludf.aggregate(15,6,(ROW(All_Risk_Apps!$A$4:$A$1233)-ROW(All_Risk_Apps!$A$4)+1)/((OR(All_Risk_Apps!$D$4:$D$1233={"High","Very High"}))*(All_Risk_Apps!$K$4:$K$1233="No")*(All_Risk_Apps!$A$4:$A$1233<>"")),5)),"") | C8: =IFERROR(INDEX(All_Risk_Apps!$D$4:$D$1233,_xludf.aggregate(15,6,(ROW(All_Risk_Apps!$A$4:$A$1233)-ROW(All_Risk_Apps!$A$4)+1)/((OR(All_Risk_Apps!$D$4:$D$1233={"High","Very High"}))*(All_Risk_Apps!$K$4:$K$1233="No")*(All_Risk_Apps!$A$4:$A$1233<>"")),5)),"") | D8: =IFERROR(INDEX(All_Risk_Apps!$C$4:$C$1233,_xludf.aggregate(15,6,(ROW(All_Risk_Apps!$A$4:$A$1233)-ROW(All_Risk_Apps!$A$4)+1)/((OR(All_Risk_Apps!$D$4:$D$1233={"High","Very High"}))*(All_Risk_Apps!$K$4:$K$1233="No")*(All_Risk_Apps!$A$4:$A$1233<>"")),5)),"") | E8: =IFERROR(INDEX(All_Risk_Apps!$E$4:$E$1233,_xludf.aggregate(15,6,(ROW(All_Risk_Apps!$A$4:$A$1233)-ROW(All_Risk_Apps!$A$4)+1)/((OR(All_Risk_Apps!$D$4:$D$1233={"High","Very High"}))*(All_Risk_Apps!$K$4:$K$1233="No")*(All_Risk_Apps!$A$4:$A$1233<>"")),5)),"") | F8: =IFERROR(INDEX(All_Risk_Apps!$F$4:$F$1233,_xludf.aggregate(15,6,(ROW(All_Risk_Apps!$A$4:$A$1233)-ROW(All_Risk_Apps!$A$4)+1)/((OR(All_Risk_Apps!$D$4:$D$1233={"High","Very High"}))*(All_Risk_Apps!$K$4:$K$1233="No")*(All_Risk_Apps!$A$4:$A$1233<>"")),5)),"") | G8: =IFERROR(INDEX(All_Risk_Apps!$I$4:$I$1233,_xludf.aggregate(15,6,(ROW(All_Risk_Apps!$A$4:$A$1233)-ROW(All_Risk_Apps!$A$4)+1)/((OR(All_Risk_Apps!$D$4:$D$1233={"High","Very High"}))*(All_Risk_Apps!$K$4:$K$1233="No")*(All_Risk_Apps!$A$4:$A$1233<>"")),5)),"") | H8: =IF(B8="","",IFERROR(INDEX(Server_Inventory!$R:$R,MATCH(B8,Server_Inventory!$Z:$Z,0)),"Not Found")) | I8: =IF(B8="","",IFERROR(INDEX(Server_Inventory!$S:$S,MATCH(B8,Server_Inventory!$Z:$Z,0)),"Not Found")) | J8: =IF(B8="","",COUNTIFS(Server_Inventory!$Z:$Z,B8,Server_Inventory!$P:$P,"R-RETIRED_IN_CMDB")) | K8: =IF(B8="","",IFERROR(INDEX(Container_Inventory!$F:$F,MATCH(B8,Container_Inventory!$L:$L,0)),"Not Found")) | L8: =IF(B8="","",IF(COUNTIF(Finding_List!$A:$A,B8)>0,"Yes","No")) | M8: =IF(B8="","",COUNTIF(Server_Inventory!$Z:$Z,B8)) | N8: =IF(B8="","",COUNTIF(Container_Inventory!$L:$L,B8))
A9: =IFERROR(INDEX(All_Risk_Apps!$A$4:$A$1233,_xludf.aggregate(15,6,(ROW(All_Risk_Apps!$A$4:$A$1233)-ROW(All_Risk_Apps!$A$4)+1)/((OR(All_Risk_Apps!$D$4:$D$1233={"High","Very High"}))*(All_Risk_Apps!$K$4:$K$1233="No")*(All_Risk_Apps!$A$4:$A$1233<>"")),6)),"") | B9: =IFERROR(INDEX(All_Risk_Apps!$B$4:$B$1233,_xludf.aggregate(15,6,(ROW(All_Risk_Apps!$A$4:$A$1233)-ROW(All_Risk_Apps!$A$4)+1)/((OR(All_Risk_Apps!$D$4:$D$1233={"High","Very High"}))*(All_Risk_Apps!$K$4:$K$1233="No")*(All_Risk_Apps!$A$4:$A$1233<>"")),6)),"") | C9: =IFERROR(INDEX(All_Risk_Apps!$D$4:$D$1233,_xludf.aggregate(15,6,(ROW(All_Risk_Apps!$A$4:$A$1233)-ROW(All_Risk_Apps!$A$4)+1)/((OR(All_Risk_Apps!$D$4:$D$1233={"High","Very High"}))*(All_Risk_Apps!$K$4:$K$1233="No")*(All_Risk_Apps!$A$4:$A$1233<>"")),6)),"") | D9: =IFERROR(INDEX(All_Risk_Apps!$C$4:$C$1233,_xludf.aggregate(15,6,(ROW(All_Risk_Apps!$A$4:$A$1233)-ROW(All_Risk_Apps!$A$4)+1)/((OR(All_Risk_Apps!$D$4:$D$1233={"High","Very High"}))*(All_Risk_Apps!$K$4:$K$1233="No")*(All_Risk_Apps!$A$4:$A$1233<>"")),6)),"") | E9: =IFERROR(INDEX(All_Risk_Apps!$E$4:$E$1233,_xludf.aggregate(15,6,(ROW(All_Risk_Apps!$A$4:$A$1233)-ROW(All_Risk_Apps!$A$4)+1)/((OR(All_Risk_Apps!$D$4:$D$1233={"High","Very High"}))*(All_Risk_Apps!$K$4:$K$1233="No")*(All_Risk_Apps!$A$4:$A$1233<>"")),6)),"") | F9: =IFERROR(INDEX(All_Risk_Apps!$F$4:$F$1233,_xludf.aggregate(15,6,(ROW(All_Risk_Apps!$A$4:$A$1233)-ROW(All_Risk_Apps!$A$4)+1)/((OR(All_Risk_Apps!$D$4:$D$1233={"High","Very High"}))*(All_Risk_Apps!$K$4:$K$1233="No")*(All_Risk_Apps!$A$4:$A$1233<>"")),6)),"") | G9: =IFERROR(INDEX(All_Risk_Apps!$I$4:$I$1233,_xludf.aggregate(15,6,(ROW(All_Risk_Apps!$A$4:$A$1233)-ROW(All_Risk_Apps!$A$4)+1)/((OR(All_Risk_Apps!$D$4:$D$1233={"High","Very High"}))*(All_Risk_Apps!$K$4:$K$1233="No")*(All_Risk_Apps!$A$4:$A$1233<>"")),6)),"") | H9: =IF(B9="","",IFERROR(INDEX(Server_Inventory!$R:$R,MATCH(B9,Server_Inventory!$Z:$Z,0)),"Not Found")) | I9: =IF(B9="","",IFERROR(INDEX(Server_Inventory!$S:$S,MATCH(B9,Server_Inventory!$Z:$Z,0)),"Not Found")) | J9: =IF(B9="","",COUNTIFS(Server_Inventory!$Z:$Z,B9,Server_Inventory!$P:$P,"R-RETIRED_IN_CMDB")) | K9: =IF(B9="","",IFERROR(INDEX(Container_Inventory!$F:$F,MATCH(B9,Container_Inventory!$L:$L,0)),"Not Found")) | L9: =IF(B9="","",IF(COUNTIF(Finding_List!$A:$A,B9)>0,"Yes","No")) | M9: =IF(B9="","",COUNTIF(Server_Inventory!$Z:$Z,B9)) | N9: =IF(B9="","",COUNTIF(Container_Inventory!$L:$L,B9))
A10: =IFERROR(INDEX(All_Risk_Apps!$A$4:$A$1233,_xludf.aggregate(15,6,(ROW(All_Risk_Apps!$A$4:$A$1233)-ROW(All_Risk_Apps!$A$4)+1)/((OR(All_Risk_Apps!$D$4:$D$1233={"High","Very High"}))*(All_Risk_Apps!$K$4:$K$1233="No")*(All_Risk_Apps!$A$4:$A$1233<>"")),7)),"") | B10: =IFERROR(INDEX(All_Risk_Apps!$B$4:$B$1233,_xludf.aggregate(15,6,(ROW(All_Risk_Apps!$A$4:$A$1233)-ROW(All_Risk_Apps!$A$4)+1)/((OR(All_Risk_Apps!$D$4:$D$1233={"High","Very High"}))*(All_Risk_Apps!$K$4:$K$1233="No")*(All_Risk_Apps!$A$4:$A$1233<>"")),7)),"") | C10: =IFERROR(INDEX(All_Risk_Apps!$D$4:$D$1233,_xludf.aggregate(15,6,(ROW(All_Risk_Apps!$A$4:$A$1233)-ROW(All_Risk_Apps!$A$4)+1)/((OR(All_Risk_Apps!$D$4:$D$1233={"High","Very High"}))*(All_Risk_Apps!$K$4:$K$1233="No")*(All_Risk_Apps!$A$4:$A$1233<>"")),7)),"") | D10: =IFERROR(INDEX(All_Risk_Apps!$C$4:$C$1233,_xludf.aggregate(15,6,(ROW(All_Risk_Apps!$A$4:$A$1233)-ROW(All_Risk_Apps!$A$4)+1)/((OR(All_Risk_Apps!$D$4:$D$1233={"High","Very High"}))*(All_Risk_Apps!$K$4:$K$1233="No")*(All_Risk_Apps!$A$4:$A$1233<>"")),7)),"") | E10: =IFERROR(INDEX(All_Risk_Apps!$E$4:$E$1233,_xludf.aggregate(15,6,(ROW(All_Risk_Apps!$A$4:$A$1233)-ROW(All_Risk_Apps!$A$4)+1)/((OR(All_Risk_Apps!$D$4:$D$1233={"High","Very High"}))*(All_Risk_Apps!$K$4:$K$1233="No")*(All_Risk_Apps!$A$4:$A$1233<>"")),7)),"") | F10: =IFERROR(INDEX(All_Risk_Apps!$F$4:$F$1233,_xludf.aggregate(15,6,(ROW(All_Risk_Apps!$A$4:$A$1233)-ROW(All_Risk_Apps!$A$4)+1)/((OR(All_Risk_Apps!$D$4:$D$1233={"High","Very High"}))*(All_Risk_Apps!$K$4:$K$1233="No")*(All_Risk_Apps!$A$4:$A$1233<>"")),7)),"") | G10: =IFERROR(INDEX(All_Risk_Apps!$I$4:$I$1233,_xludf.aggregate(15,6,(ROW(All_Risk_Apps!$A$4:$A$1233)-ROW(All_Risk_Apps!$A$4)+1)/((OR(All_Risk_Apps!$D$4:$D$1233={"High","Very High"}))*(All_Risk_Apps!$K$4:$K$1233="No")*(All_Risk_Apps!$A$4:$A$1233<>"")),7)),"") | H10: =IF(B10="","",IFERROR(INDEX(Server_Inventory!$R:$R,MATCH(B10,Server_Inventory!$Z:$Z,0)),"Not Found")) | I10: =IF(B10="","",IFERROR(INDEX(Server_Inventory!$S:$S,MATCH(B10,Server_Inventory!$Z:$Z,0)),"Not Found")) | J10: =IF(B10="","",COUNTIFS(Server_Inventory!$Z:$Z,B10,Server_Inventory!$P:$P,"R-RETIRED_IN_CMDB")) | K10: =IF(B10="","",IFERROR(INDEX(Container_Inventory!$F:$F,MATCH(B10,Container_Inventory!$L:$L,0)),"Not Found")) | L10: =IF(B10="","",IF(COUNTIF(Finding_List!$A:$A,B10)>0,"Yes","No")) | M10: =IF(B10="","",COUNTIF(Server_Inventory!$Z:$Z,B10)) | N10: =IF(B10="","",COUNTIF(Container_Inventory!$L:$L,B10))
A11: =IFERROR(INDEX(All_Risk_Apps!$A$4:$A$1233,_xludf.aggregate(15,6,(ROW(All_Risk_Apps!$A$4:$A$1233)-ROW(All_Risk_Apps!$A$4)+1)/((OR(All_Risk_Apps!$D$4:$D$1233={"High","Very High"}))*(All_Risk_Apps!$K$4:$K$1233="No")*(All_Risk_Apps!$A$4:$A$1233<>"")),8)),"") | B11: =IFERROR(INDEX(All_Risk_Apps!$B$4:$B$1233,_xludf.aggregate(15,6,(ROW(All_Risk_Apps!$A$4:$A$1233)-ROW(All_Risk_Apps!$A$4)+1)/((OR(All_Risk_Apps!$D$4:$D$1233={"High","Very High"}))*(All_Risk_Apps!$K$4:$K$1233="No")*(All_Risk_Apps!$A$4:$A$1233<>"")),8)),"") | C11: =IFERROR(INDEX(All_Risk_Apps!$D$4:$D$1233,_xludf.aggregate(15,6,(ROW(All_Risk_Apps!$A$4:$A$1233)-ROW(All_Risk_Apps!$A$4)+1)/((OR(All_Risk_Apps!$D$4:$D$1233={"High","Very High"}))*(All_Risk_Apps!$K$4:$K$1233="No")*(All_Risk_Apps!$A$4:$A$1233<>"")),8)),"") | D11: =IFERROR(INDEX(All_Risk_Apps!$C$4:$C$1233,_xludf.aggregate(15,6,(ROW(All_Risk_Apps!$A$4:$A$1233)-ROW(All_Risk_Apps!$A$4)+1)/((OR(All_Risk_Apps!$D$4:$D$1233={"High","Very High"}))*(All_Risk_Apps!$K$4:$K$1233="No")*(All_Risk_Apps!$A$4:$A$1233<>"")),8)),"") | E11: =IFERROR(INDEX(All_Risk_Apps!$E$4:$E$1233,_xludf.aggregate(15,6,(ROW(All_Risk_Apps!$A$4:$A$1233)-ROW(All_Risk_Apps!$A$4)+1)/((OR(All_Risk_Apps!$D$4:$D$1233={"High","Very High"}))*(All_Risk_Apps!$K$4:$K$1233="No")*(All_Risk_Apps!$A$4:$A$1233<>"")),8)),"") | F11: =IFERROR(INDEX(All_Risk_Apps!$F$4:$F$1233,_xludf.aggregate(15,6,(ROW(All_Risk_Apps!$A$4:$A$1233)-ROW(All_Risk_Apps!$A$4)+1)/((OR(All_Risk_Apps!$D$4:$D$1233={"High","Very High"}))*(All_Risk_Apps!$K$4:$K$1233="No")*(All_Risk_Apps!$A$4:$A$1233<>"")),8)),"") | G11: =IFERROR(INDEX(All_Risk_Apps!$I$4:$I$1233,_xludf.aggregate(15,6,(ROW(All_Risk_Apps!$A$4:$A$1233)-ROW(All_Risk_Apps!$A$4)+1)/((OR(All_Risk_Apps!$D$4:$D$1233={"High","Very High"}))*(All_Risk_Apps!$K$4:$K$1233="No")*(All_Risk_Apps!$A$4:$A$1233<>"")),8)),"") | H11: =IF(B11="","",IFERROR(INDEX(Server_Inventory!$R:$R,MATCH(B11,Server_Inventory!$Z:$Z,0)),"Not Found")) | I11: =IF(B11="","",IFERROR(INDEX(Server_Inventory!$S:$S,MATCH(B11,Server_Inventory!$Z:$Z,0)),"Not Found")) | J11: =IF(B11="","",COUNTIFS(Server_Inventory!$Z:$Z,B11,Server_Inventory!$P:$P,"R-RETIRED_IN_CMDB")) | K11: =IF(B11="","",IFERROR(INDEX(Container_Inventory!$F:$F,MATCH(B11,Container_Inventory!$L:$L,0)),"Not Found")) | L11: =IF(B11="","",IF(COUNTIF(Finding_List!$A:$A,B11)>0,"Yes","No")) | M11: =IF(B11="","",COUNTIF(Server_Inventory!$Z:$Z,B11)) | N11: =IF(B11="","",COUNTIF(Container_Inventory!$L:$L,B11))
A12: =IFERROR(INDEX(All_Risk_Apps!$A$4:$A$1233,_xludf.aggregate(15,6,(ROW(All_Risk_Apps!$A$4:$A$1233)-ROW(All_Risk_Apps!$A$4)+1)/((OR(All_Risk_Apps!$D$4:$D$1233={"High","Very High"}))*(All_Risk_Apps!$K$4:$K$1233="No")*(All_Risk_Apps!$A$4:$A$1233<>"")),9)),"") | B12: =IFERROR(INDEX(All_Risk_Apps!$B$4:$B$1233,_xludf.aggregate(15,6,(ROW(All_Risk_Apps!$A$4:$A$1233)-ROW(All_Risk_Apps!$A$4)+1)/((OR(All_Risk_Apps!$D$4:$D$1233={"High","Very High"}))*(All_Risk_Apps!$K$4:$K$1233="No")*(All_Risk_Apps!$A$4:$A$1233<>"")),9)),"") | C12: =IFERROR(INDEX(All_Risk_Apps!$D$4:$D$1233,_xludf.aggregate(15,6,(ROW(All_Risk_Apps!$A$4:$A$1233)-ROW(All_Risk_Apps!$A$4)+1)/((OR(All_Risk_Apps!$D$4:$D$1233={"High","Very High"}))*(All_Risk_Apps!$K$4:$K$1233="No")*(All_Risk_Apps!$A$4:$A$1233<>"")),9)),"") | D12: =IFERROR(INDEX(All_Risk_Apps!$C$4:$C$1233,_xludf.aggregate(15,6,(ROW(All_Risk_Apps!$A$4:$A$1233)-ROW(All_Risk_Apps!$A$4)+1)/((OR(All_Risk_Apps!$D$4:$D$1233={"High","Very High"}))*(All_Risk_Apps!$K$4:$K$1233="No")*(All_Risk_Apps!$A$4:$A$1233<>"")),9)),"") | E12: =IFERROR(INDEX(All_Risk_Apps!$E$4:$E$1233,_xludf.aggregate(15,6,(ROW(All_Risk_Apps!$A$4:$A$1233)-ROW(All_Risk_Apps!$A$4)+1)/((OR(All_Risk_Apps!$D$4:$D$1233={"High","Very High"}))*(All_Risk_Apps!$K$4:$K$1233="No")*(All_Risk_Apps!$A$4:$A$1233<>"")),9)),"") | F12: =IFERROR(INDEX(All_Risk_Apps!$F$4:$F$1233,_xludf.aggregate(15,6,(ROW(All_Risk_Apps!$A$4:$A$1233)-ROW(All_Risk_Apps!$A$4)+1)/((OR(All_Risk_Apps!$D$4:$D$1233={"High","Very High"}))*(All_Risk_Apps!$K$4:$K$1233="No")*(All_Risk_Apps!$A$4:$A$1233<>"")),9)),"") | G12: =IFERROR(INDEX(All_Risk_Apps!$I$4:$I$1233,_xludf.aggregate(15,6,(ROW(All_Risk_Apps!$A$4:$A$1233)-ROW(All_Risk_Apps!$A$4)+1)/((OR(All_Risk_Apps!$D$4:$D$1233={"High","Very High"}))*(All_Risk_Apps!$K$4:$K$1233="No")*(All_Risk_Apps!$A$4:$A$1233<>"")),9)),"") | H12: =IF(B12="","",IFERROR(INDEX(Server_Inventory!$R:$R,MATCH(B12,Server_Inventory!$Z:$Z,0)),"Not Found")) | I12: =IF(B12="","",IFERROR(INDEX(Server_Inventory!$S:$S,MATCH(B12,Server_Inventory!$Z:$Z,0)),"Not Found")) | J12: =IF(B12="","",COUNTIFS(Server_Inventory!$Z:$Z,B12,Server_Inventory!$P:$P,"R-RETIRED_IN_CMDB")) | K12: =IF(B12="","",IFERROR(INDEX(Container_Inventory!$F:$F,MATCH(B12,Container_Inventory!$L:$L,0)),"Not Found")) | L12: =IF(B12="","",IF(COUNTIF(Finding_List!$A:$A,B12)>0,"Yes","No")) | M12: =IF(B12="","",COUNTIF(Server_Inventory!$Z:$Z,B12)) | N12: =IF(B12="","",COUNTIF(Container_Inventory!$L:$L,B12))
A13: =IFERROR(INDEX(All_Risk_Apps!$A$4:$A$1233,_xludf.aggregate(15,6,(ROW(All_Risk_Apps!$A$4:$A$1233)-ROW(All_Risk_Apps!$A$4)+1)/((OR(All_Risk_Apps!$D$4:$D$1233={"High","Very High"}))*(All_Risk_Apps!$K$4:$K$1233="No")*(All_Risk_Apps!$A$4:$A$1233<>"")),10)),"") | B13: =IFERROR(INDEX(All_Risk_Apps!$B$4:$B$1233,_xludf.aggregate(15,6,(ROW(All_Risk_Apps!$A$4:$A$1233)-ROW(All_Risk_Apps!$A$4)+1)/((OR(All_Risk_Apps!$D$4:$D$1233={"High","Very High"}))*(All_Risk_Apps!$K$4:$K$1233="No")*(All_Risk_Apps!$A$4:$A$1233<>"")),10)),"") | C13: =IFERROR(INDEX(All_Risk_Apps!$D$4:$D$1233,_xludf.aggregate(15,6,(ROW(All_Risk_Apps!$A$4:$A$1233)-ROW(All_Risk_Apps!$A$4)+1)/((OR(All_Risk_Apps!$D$4:$D$1233={"High","Very High"}))*(All_Risk_Apps!$K$4:$K$1233="No")*(All_Risk_Apps!$A$4:$A$1233<>"")),10)),"") | D13: =IFERROR(INDEX(All_Risk_Apps!$C$4:$C$1233,_xludf.aggregate(15,6,(ROW(All_Risk_Apps!$A$4:$A$1233)-ROW(All_Risk_Apps!$A$4)+1)/((OR(All_Risk_Apps!$D$4:$D$1233={"High","Very High"}))*(All_Risk_Apps!$K$4:$K$1233="No")*(All_Risk_Apps!$A$4:$A$1233<>"")),10)),"") | E13: =IFERROR(INDEX(All_Risk_Apps!$E$4:$E$1233,_xludf.aggregate(15,6,(ROW(All_Risk_Apps!$A$4:$A$1233)-ROW(All_Risk_Apps!$A$4)+1)/((OR(All_Risk_Apps!$D$4:$D$1233={"High","Very High"}))*(All_Risk_Apps!$K$4:$K$1233="No")*(All_Risk_Apps!$A$4:$A$1233<>"")),10)),"") | F13: =IFERROR(INDEX(All_Risk_Apps!$F$4:$F$1233,_xludf.aggregate(15,6,(ROW(All_Risk_Apps!$A$4:$A$1233)-ROW(All_Risk_Apps!$A$4)+1)/((OR(All_Risk_Apps!$D$4:$D$1233={"High","Very High"}))*(All_Risk_Apps!$K$4:$K$1233="No")*(All_Risk_Apps!$A$4:$A$1233<>"")),10)),"") | G13: =IFERROR(INDEX(All_Risk_Apps!$I$4:$I$1233,_xludf.aggregate(15,6,(ROW(All_Risk_Apps!$A$4:$A$1233)-ROW(All_Risk_Apps!$A$4)+1)/((OR(All_Risk_Apps!$D$4:$D$1233={"High","Very High"}))*(All_Risk_Apps!$K$4:$K$1233="No")*(All_Risk_Apps!$A$4:$A$1233<>"")),10)),"") | H13: =IF(B13="","",IFERROR(INDEX(Server_Inventory!$R:$R,MATCH(B13,Server_Inventory!$Z:$Z,0)),"Not Found")) | I13: =IF(B13="","",IFERROR(INDEX(Server_Inventory!$S:$S,MATCH(B13,Server_Inventory!$Z:$Z,0)),"Not Found")) | J13: =IF(B13="","",COUNTIFS(Server_Inventory!$Z:$Z,B13,Server_Inventory!$P:$P,"R-RETIRED_IN_CMDB")) | K13: =IF(B13="","",IFERROR(INDEX(Container_Inventory!$F:$F,MATCH(B13,Container_Inventory!$L:$L,0)),"Not Found")) | L13: =IF(B13="","",IF(COUNTIF(Finding_List!$A:$A,B13)>0,"Yes","No")) | M13: =IF(B13="","",COUNTIF(Server_Inventory!$Z:$Z,B13)) | N13: =IF(B13="","",COUNTIF(Container_Inventory!$L:$L,B13))
A14: =IFERROR(INDEX(All_Risk_Apps!$A$4:$A$1233,_xludf.aggregate(15,6,(ROW(All_Risk_Apps!$A$4:$A$1233)-ROW(All_Risk_Apps!$A$4)+1)/((OR(All_Risk_Apps!$D$4:$D$1233={"High","Very High"}))*(All_Risk_Apps!$K$4:$K$1233="No")*(All_Risk_Apps!$A$4:$A$1233<>"")),11)),"") | B14: =IFERROR(INDEX(All_Risk_Apps!$B$4:$B$1233,_xludf.aggregate(15,6,(ROW(All_Risk_Apps!$A$4:$A$1233)-ROW(All_Risk_Apps!$A$4)+1)/((OR(All_Risk_Apps!$D$4:$D$1233={"High","Very High"}))*(All_Risk_Apps!$K$4:$K$1233="No")*(All_Risk_Apps!$A$4:$A$1233<>"")),11)),"") | C14: =IFERROR(INDEX(All_Risk_Apps!$D$4:$D$1233,_xludf.aggregate(15,6,(ROW(All_Risk_Apps!$A$4:$A$1233)-ROW(All_Risk_Apps!$A$4)+1)/((OR(All_Risk_Apps!$D$4:$D$1233={"High","Very High"}))*(All_Risk_Apps!$K$4:$K$1233="No")*(All_Risk_Apps!$A$4:$A$1233<>"")),11)),"") | D14: =IFERROR(INDEX(All_Risk_Apps!$C$4:$C$1233,_xludf.aggregate(15,6,(ROW(All_Risk_Apps!$A$4:$A$1233)-ROW(All_Risk_Apps!$A$4)+1)/((OR(All_Risk_Apps!$D$4:$D$1233={"High","Very High"}))*(All_Risk_Apps!$K$4:$K$1233="No")*(All_Risk_Apps!$A$4:$A$1233<>"")),11)),"") | E14: =IFERROR(INDEX(All_Risk_Apps!$E$4:$E$1233,_xludf.aggregate(15,6,(ROW(All_Risk_Apps!$A$4:$A$1233)-ROW(All_Risk_Apps!$A$4)+1)/((OR(All_Risk_Apps!$D$4:$D$1233={"High","Very High"}))*(All_Risk_Apps!$K$4:$K$1233="No")*(All_Risk_Apps!$A$4:$A$1233<>"")),11)),"") | F14: =IFERROR(INDEX(All_Risk_Apps!$F$4:$F$1233,_xludf.aggregate(15,6,(ROW(All_Risk_Apps!$A$4:$A$1233)-ROW(All_Risk_Apps!$A$4)+1)/((OR(All_Risk_Apps!$D$4:$D$1233={"High","Very High"}))*(All_Risk_Apps!$K$4:$K$1233="No")*(All_Risk_Apps!$A$4:$A$1233<>"")),11)),"") | G14: =IFERROR(INDEX(All_Risk_Apps!$I$4:$I$1233,_xludf.aggregate(15,6,(ROW(All_Risk_Apps!$A$4:$A$1233)-ROW(All_Risk_Apps!$A$4)+1)/((OR(All_Risk_Apps!$D$4:$D$1233={"High","Very High"}))*(All_Risk_Apps!$K$4:$K$1233="No")*(All_Risk_Apps!$A$4:$A$1233<>"")),11)),"") | H14: =IF(B14="","",IFERROR(INDEX(Server_Inventory!$R:$R,MATCH(B14,Server_Inventory!$Z:$Z,0)),"Not Found")) | I14: =IF(B14="","",IFERROR(INDEX(Server_Inventory!$S:$S,MATCH(B14,Server_Inventory!$Z:$Z,0)),"Not Found")) | J14: =IF(B14="","",COUNTIFS(Server_Inventory!$Z:$Z,B14,Server_Inventory!$P:$P,"R-RETIRED_IN_CMDB")) | K14: =IF(B14="","",IFERROR(INDEX(Container_Inventory!$F:$F,MATCH(B14,Container_Inventory!$L:$L,0)),"Not Found")) | L14: =IF(B14="","",IF(COUNTIF(Finding_List!$A:$A,B14)>0,"Yes","No")) | M14: =IF(B14="","",COUNTIF(Server_Inventory!$Z:$Z,B14)) | N14: =IF(B14="","",COUNTIF(Container_Inventory!$L:$L,B14))
A15: =IFERROR(INDEX(All_Risk_Apps!$A$4:$A$1233,_xludf.aggregate(15,6,(ROW(All_Risk_Apps!$A$4:$A$1233)-ROW(All_Risk_Apps!$A$4)+1)/((OR(All_Risk_Apps!$D$4:$D$1233={"High","Very High"}))*(All_Risk_Apps!$K$4:$K$1233="No")*(All_Risk_Apps!$A$4:$A$1233<>"")),12)),"") | B15: =IFERROR(INDEX(All_Risk_Apps!$B$4:$B$1233,_xludf.aggregate(15,6,(ROW(All_Risk_Apps!$A$4:$A$1233)-ROW(All_Risk_Apps!$A$4)+1)/((OR(All_Risk_Apps!$D$4:$D$1233={"High","Very High"}))*(All_Risk_Apps!$K$4:$K$1233="No")*(All_Risk_Apps!$A$4:$A$1233<>"")),12)),"") | C15: =IFERROR(INDEX(All_Risk_Apps!$D$4:$D$1233,_xludf.aggregate(15,6,(ROW(All_Risk_Apps!$A$4:$A$1233)-ROW(All_Risk_Apps!$A$4)+1)/((OR(All_Risk_Apps!$D$4:$D$1233={"High","Very High"}))*(All_Risk_Apps!$K$4:$K$1233="No")*(All_Risk_Apps!$A$4:$A$1233<>"")),12)),"") | D15: =IFERROR(INDEX(All_Risk_Apps!$C$4:$C$1233,_xludf.aggregate(15,6,(ROW(All_Risk_Apps!$A$4:$A$1233)-ROW(All_Risk_Apps!$A$4)+1)/((OR(All_Risk_Apps!$D$4:$D$1233={"High","Very High"}))*(All_Risk_Apps!$K$4:$K$1233="No")*(All_Risk_Apps!$A$4:$A$1233<>"")),12)),"") | E15: =IFERROR(INDEX(All_Risk_Apps!$E$4:$E$1233,_xludf.aggregate(15,6,(ROW(All_Risk_Apps!$A$4:$A$1233)-ROW(All_Risk_Apps!$A$4)+1)/((OR(All_Risk_Apps!$D$4:$D$1233={"High","Very High"}))*(All_Risk_Apps!$K$4:$K$1233="No")*(All_Risk_Apps!$A$4:$A$1233<>"")),12)),"") | F15: =IFERROR(INDEX(All_Risk_Apps!$F$4:$F$1233,_xludf.aggregate(15,6,(ROW(All_Risk_Apps!$A$4:$A$1233)-ROW(All_Risk_Apps!$A$4)+1)/((OR(All_Risk_Apps!$D$4:$D$1233={"High","Very High"}))*(All_Risk_Apps!$K$4:$K$1233="No")*(All_Risk_Apps!$A$4:$A$1233<>"")),12)),"") | G15: =IFERROR(INDEX(All_Risk_Apps!$I$4:$I$1233,_xludf.aggregate(15,6,(ROW(All_Risk_Apps!$A$4:$A$1233)-ROW(All_Risk_Apps!$A$4)+1)/((OR(All_Risk_Apps!$D$4:$D$1233={"High","Very High"}))*(All_Risk_Apps!$K$4:$K$1233="No")*(All_Risk_Apps!$A$4:$A$1233<>"")),12)),"") | H15: =IF(B15="","",IFERROR(INDEX(Server_Inventory!$R:$R,MATCH(B15,Server_Inventory!$Z:$Z,0)),"Not Found")) | I15: =IF(B15="","",IFERROR(INDEX(Server_Inventory!$S:$S,MATCH(B15,Server_Inventory!$Z:$Z,0)),"Not Found")) | J15: =IF(B15="","",COUNTIFS(Server_Inventory!$Z:$Z,B15,Server_Inventory!$P:$P,"R-RETIRED_IN_CMDB")) | K15: =IF(B15="","",IFERROR(INDEX(Container_Inventory!$F:$F,MATCH(B15,Container_Inventory!$L:$L,0)),"Not Found")) | L15: =IF(B15="","",IF(COUNTIF(Finding_List!$A:$A,B15)>0,"Yes","No")) | M15: =IF(B15="","",COUNTIF(Server_Inventory!$Z:$Z,B15)) | N15: =IF(B15="","",COUNTIF(Container_Inventory!$L:$L,B15))
A16: =IFERROR(INDEX(All_Risk_Apps!$A$4:$A$1233,_xludf.aggregate(15,6,(ROW(All_Risk_Apps!$A$4:$A$1233)-ROW(All_Risk_Apps!$A$4)+1)/((OR(All_Risk_Apps!$D$4:$D$1233={"High","Very High"}))*(All_Risk_Apps!$K$4:$K$1233="No")*(All_Risk_Apps!$A$4:$A$1233<>"")),13)),"") | B16: =IFERROR(INDEX(All_Risk_Apps!$B$4:$B$1233,_xludf.aggregate(15,6,(ROW(All_Risk_Apps!$A$4:$A$1233)-ROW(All_Risk_Apps!$A$4)+1)/((OR(All_Risk_Apps!$D$4:$D$1233={"High","Very High"}))*(All_Risk_Apps!$K$4:$K$1233="No")*(All_Risk_Apps!$A$4:$A$1233<>"")),13)),"") | C16: =IFERROR(INDEX(All_Risk_Apps!$D$4:$D$1233,_xludf.aggregate(15,6,(ROW(All_Risk_Apps!$A$4:$A$1233)-ROW(All_Risk_Apps!$A$4)+1)/((OR(All_Risk_Apps!$D$4:$D$1233={"High","Very High"}))*(All_Risk_Apps!$K$4:$K$1233="No")*(All_Risk_Apps!$A$4:$A$1233<>"")),13)),"") | D16: =IFERROR(INDEX(All_Risk_Apps!$C$4:$C$1233,_xludf.aggregate(15,6,(ROW(All_Risk_Apps!$A$4:$A$1233)-ROW(All_Risk_Apps!$A$4)+1)/((OR(All_Risk_Apps!$D$4:$D$1233={"High","Very High"}))*(All_Risk_Apps!$K$4:$K$1233="No")*(All_Risk_Apps!$A$4:$A$1233<>"")),13)),"") | E16: =IFERROR(INDEX(All_Risk_Apps!$E$4:$E$1233,_xludf.aggregate(15,6,(ROW(All_Risk_Apps!$A$4:$A$1233)-ROW(All_Risk_Apps!$A$4)+1)/((OR(All_Risk_Apps!$D$4:$D$1233={"High","Very High"}))*(All_Risk_Apps!$K$4:$K$1233="No")*(All_Risk_Apps!$A$4:$A$1233<>"")),13)),"") | F16: =IFERROR(INDEX(All_Risk_Apps!$F$4:$F$1233,_xludf.aggregate(15,6,(ROW(All_Risk_Apps!$A$4:$A$1233)-ROW(All_Risk_Apps!$A$4)+1)/((OR(All_Risk_Apps!$D$4:$D$1233={"High","Very High"}))*(All_Risk_Apps!$K$4:$K$1233="No")*(All_Risk_Apps!$A$4:$A$1233<>"")),13)),"") | G16: =IFERROR(INDEX(All_Risk_Apps!$I$4:$I$1233,_xludf.aggregate(15,6,(ROW(All_Risk_Apps!$A$4:$A$1233)-ROW(All_Risk_Apps!$A$4)+1)/((OR(All_Risk_Apps!$D$4:$D$1233={"High","Very High"}))*(All_Risk_Apps!$K$4:$K$1233="No")*(All_Risk_Apps!$A$4:$A$1233<>"")),13)),"") | H16: =IF(B16="","",IFERROR(INDEX(Server_Inventory!$R:$R,MATCH(B16,Server_Inventory!$Z:$Z,0)),"Not Found")) | I16: =IF(B16="","",IFERROR(INDEX(Server_Inventory!$S:$S,MATCH(B16,Server_Inventory!$Z:$Z,0)),"Not Found")) | J16: =IF(B16="","",COUNTIFS(Server_Inventory!$Z:$Z,B16,Server_Inventory!$P:$P,"R-RETIRED_IN_CMDB")) | K16: =IF(B16="","",IFERROR(INDEX(Container_Inventory!$F:$F,MATCH(B16,Container_Inventory!$L:$L,0)),"Not Found")) | L16: =IF(B16="","",IF(COUNTIF(Finding_List!$A:$A,B16)>0,"Yes","No")) | M16: =IF(B16="","",COUNTIF(Server_Inventory!$Z:$Z,B16)) | N16: =IF(B16="","",COUNTIF(Container_Inventory!$L:$L,B16))
A17: =IFERROR(INDEX(All_Risk_Apps!$A$4:$A$1233,_xludf.aggregate(15,6,(ROW(All_Risk_Apps!$A$4:$A$1233)-ROW(All_Risk_Apps!$A$4)+1)/((OR(All_Risk_Apps!$D$4:$D$1233={"High","Very High"}))*(All_Risk_Apps!$K$4:$K$1233="No")*(All_Risk_Apps!$A$4:$A$1233<>"")),14)),"") | B17: =IFERROR(INDEX(All_Risk_Apps!$B$4:$B$1233,_xludf.aggregate(15,6,(ROW(All_Risk_Apps!$A$4:$A$1233)-ROW(All_Risk_Apps!$A$4)+1)/((OR(All_Risk_Apps!$D$4:$D$1233={"High","Very High"}))*(All_Risk_Apps!$K$4:$K$1233="No")*(All_Risk_Apps!$A$4:$A$1233<>"")),14)),"") | C17: =IFERROR(INDEX(All_Risk_Apps!$D$4:$D$1233,_xludf.aggregate(15,6,(ROW(All_Risk_Apps!$A$4:$A$1233)-ROW(All_Risk_Apps!$A$4)+1)/((OR(All_Risk_Apps!$D$4:$D$1233={"High","Very High"}))*(All_Risk_Apps!$K$4:$K$1233="No")*(All_Risk_Apps!$A$4:$A$1233<>"")),14)),"") | D17: =IFERROR(INDEX(All_Risk_Apps!$C$4:$C$1233,_xludf.aggregate(15,6,(ROW(All_Risk_Apps!$A$4:$A$1233)-ROW(All_Risk_Apps!$A$4)+1)/((OR(All_Risk_Apps!$D$4:$D$1233={"High","Very High"}))*(All_Risk_Apps!$K$4:$K$1233="No")*(All_Risk_Apps!$A$4:$A$1233<>"")),14)),"") | E17: =IFERROR(INDEX(All_Risk_Apps!$E$4:$E$1233,_xludf.aggregate(15,6,(ROW(All_Risk_Apps!$A$4:$A$1233)-ROW(All_Risk_Apps!$A$4)+1)/((OR(All_Risk_Apps!$D$4:$D$1233={"High","Very High"}))*(All_Risk_Apps!$K$4:$K$1233="No")*(All_Risk_Apps!$A$4:$A$1233<>"")),14)),"") | F17: =IFERROR(INDEX(All_Risk_Apps!$F$4:$F$1233,_xludf.aggregate(15,6,(ROW(All_Risk_Apps!$A$4:$A$1233)-ROW(All_Risk_Apps!$A$4)+1)/((OR(All_Risk_Apps!$D$4:$D$1233={"High","Very High"}))*(All_Risk_Apps!$K$4:$K$1233="No")*(All_Risk_Apps!$A$4:$A$1233<>"")),14)),"") | G17: =IFERROR(INDEX(All_Risk_Apps!$I$4:$I$1233,_xludf.aggregate(15,6,(ROW(All_Risk_Apps!$A$4:$A$1233)-ROW(All_Risk_Apps!$A$4)+1)/((OR(All_Risk_Apps!$D$4:$D$1233={"High","Very High"}))*(All_Risk_Apps!$K$4:$K$1233="No")*(All_Risk_Apps!$A$4:$A$1233<>"")),14)),"") | H17: =IF(B17="","",IFERROR(INDEX(Server_Inventory!$R:$R,MATCH(B17,Server_Inventory!$Z:$Z,0)),"Not Found")) | I17: =IF(B17="","",IFERROR(INDEX(Server_Inventory!$S:$S,MATCH(B17,Server_Inventory!$Z:$Z,0)),"Not Found")) | J17: =IF(B17="","",COUNTIFS(Server_Inventory!$Z:$Z,B17,Server_Inventory!$P:$P,"R-RETIRED_IN_CMDB")) | K17: =IF(B17="","",IFERROR(INDEX(Container_Inventory!$F:$F,MATCH(B17,Container_Inventory!$L:$L,0)),"Not Found")) | L17: =IF(B17="","",IF(COUNTIF(Finding_List!$A:$A,B17)>0,"Yes","No")) | M17: =IF(B17="","",COUNTIF(Server_Inventory!$Z:$Z,B17)) | N17: =IF(B17="","",COUNTIF(Container_Inventory!$L:$L,B17))
A18: =IFERROR(INDEX(All_Risk_Apps!$A$4:$A$1233,_xludf.aggregate(15,6,(ROW(All_Risk_Apps!$A$4:$A$1233)-ROW(All_Risk_Apps!$A$4)+1)/((OR(All_Risk_Apps!$D$4:$D$1233={"High","Very High"}))*(All_Risk_Apps!$K$4:$K$1233="No")*(All_Risk_Apps!$A$4:$A$1233<>"")),15)),"") | B18: =IFERROR(INDEX(All_Risk_Apps!$B$4:$B$1233,_xludf.aggregate(15,6,(ROW(All_Risk_Apps!$A$4:$A$1233)-ROW(All_Risk_Apps!$A$4)+1)/((OR(All_Risk_Apps!$D$4:$D$1233={"High","Very High"}))*(All_Risk_Apps!$K$4:$K$1233="No")*(All_Risk_Apps!$A$4:$A$1233<>"")),15)),"") | C18: =IFERROR(INDEX(All_Risk_Apps!$D$4:$D$1233,_xludf.aggregate(15,6,(ROW(All_Risk_Apps!$A$4:$A$1233)-ROW(All_Risk_Apps!$A$4)+1)/((OR(All_Risk_Apps!$D$4:$D$1233={"High","Very High"}))*(All_Risk_Apps!$K$4:$K$1233="No")*(All_Risk_Apps!$A$4:$A$1233<>"")),15)),"") | D18: =IFERROR(INDEX(All_Risk_Apps!$C$4:$C$1233,_xludf.aggregate(15,6,(ROW(All_Risk_Apps!$A$4:$A$1233)-ROW(All_Risk_Apps!$A$4)+1)/((OR(All_Risk_Apps!$D$4:$D$1233={"High","Very High"}))*(All_Risk_Apps!$K$4:$K$1233="No")*(All_Risk_Apps!$A$4:$A$1233<>"")),15)),"") | E18: =IFERROR(INDEX(All_Risk_Apps!$E$4:$E$1233,_xludf.aggregate(15,6,(ROW(All_Risk_Apps!$A$4:$A$1233)-ROW(All_Risk_Apps!$A$4)+1)/((OR(All_Risk_Apps!$D$4:$D$1233={"High","Very High"}))*(All_Risk_Apps!$K$4:$K$1233="No")*(All_Risk_Apps!$A$4:$A$1233<>"")),15)),"") | F18: =IFERROR(INDEX(All_Risk_Apps!$F$4:$F$1233,_xludf.aggregate(15,6,(ROW(All_Risk_Apps!$A$4:$A$1233)-ROW(All_Risk_Apps!$A$4)+1)/((OR(All_Risk_Apps!$D$4:$D$1233={"High","Very High"}))*(All_Risk_Apps!$K$4:$K$1233="No")*(All_Risk_Apps!$A$4:$A$1233<>"")),15)),"") | G18: =IFERROR(INDEX(All_Risk_Apps!$I$4:$I$1233,_xludf.aggregate(15,6,(ROW(All_Risk_Apps!$A$4:$A$1233)-ROW(All_Risk_Apps!$A$4)+1)/((OR(All_Risk_Apps!$D$4:$D$1233={"High","Very High"}))*(All_Risk_Apps!$K$4:$K$1233="No")*(All_Risk_Apps!$A$4:$A$1233<>"")),15)),"") | H18: =IF(B18="","",IFERROR(INDEX(Server_Inventory!$R:$R,MATCH(B18,Server_Inventory!$Z:$Z,0)),"Not Found")) | I18: =IF(B18="","",IFERROR(INDEX(Server_Inventory!$S:$S,MATCH(B18,Server_Inventory!$Z:$Z,0)),"Not Found")) | J18: =IF(B18="","",COUNTIFS(Server_Inventory!$Z:$Z,B18,Server_Inventory!$P:$P,"R-RETIRED_IN_CMDB")) | K18: =IF(B18="","",IFERROR(INDEX(Container_Inventory!$F:$F,MATCH(B18,Container_Inventory!$L:$L,0)),"Not Found")) | L18: =IF(B18="","",IF(COUNTIF(Finding_List!$A:$A,B18)>0,"Yes","No")) | M18: =IF(B18="","",COUNTIF(Server_Inventory!$Z:$Z,B18)) | N18: =IF(B18="","",COUNTIF(Container_Inventory!$L:$L,B18))
A19: =IFERROR(INDEX(All_Risk_Apps!$A$4:$A$1233,_xludf.aggregate(15,6,(ROW(All_Risk_Apps!$A$4:$A$1233)-ROW(All_Risk_Apps!$A$4)+1)/((OR(All_Risk_Apps!$D$4:$D$1233={"High","Very High"}))*(All_Risk_Apps!$K$4:$K$1233="No")*(All_Risk_Apps!$A$4:$A$1233<>"")),16)),"") | B19: =IFERROR(INDEX(All_Risk_Apps!$B$4:$B$1233,_xludf.aggregate(15,6,(ROW(All_Risk_Apps!$A$4:$A$1233)-ROW(All_Risk_Apps!$A$4)+1)/((OR(All_Risk_Apps!$D$4:$D$1233={"High","Very High"}))*(All_Risk_Apps!$K$4:$K$1233="No")*(All_Risk_Apps!$A$4:$A$1233<>"")),16)),"") | C19: =IFERROR(INDEX(All_Risk_Apps!$D$4:$D$1233,_xludf.aggregate(15,6,(ROW(All_Risk_Apps!$A$4:$A$1233)-ROW(All_Risk_Apps!$A$4)+1)/((OR(All_Risk_Apps!$D$4:$D$1233={"High","Very High"}))*(All_Risk_Apps!$K$4:$K$1233="No")*(All_Risk_Apps!$A$4:$A$1233<>"")),16)),"") | D19: =IFERROR(INDEX(All_Risk_Apps!$C$4:$C$1233,_xludf.aggregate(15,6,(ROW(All_Risk_Apps!$A$4:$A$1233)-ROW(All_Risk_Apps!$A$4)+1)/((OR(All_Risk_Apps!$D$4:$D$1233={"High","Very High"}))*(All_Risk_Apps!$K$4:$K$1233="No")*(All_Risk_Apps!$A$4:$A$1233<>"")),16)),"") | E19: =IFERROR(INDEX(All_Risk_Apps!$E$4:$E$1233,_xludf.aggregate(15,6,(ROW(All_Risk_Apps!$A$4:$A$1233)-ROW(All_Risk_Apps!$A$4)+1)/((OR(All_Risk_Apps!$D$4:$D$1233={"High","Very High"}))*(All_Risk_Apps!$K$4:$K$1233="No")*(All_Risk_Apps!$A$4:$A$1233<>"")),16)),"") | F19: =IFERROR(INDEX(All_Risk_Apps!$F$4:$F$1233,_xludf.aggregate(15,6,(ROW(All_Risk_Apps!$A$4:$A$1233)-ROW(All_Risk_Apps!$A$4)+1)/((OR(All_Risk_Apps!$D$4:$D$1233={"High","Very High"}))*(All_Risk_Apps!$K$4:$K$1233="No")*(All_Risk_Apps!$A$4:$A$1233<>"")),16)),"") | G19: =IFERROR(INDEX(All_Risk_Apps!$I$4:$I$1233,_xludf.aggregate(15,6,(ROW(All_Risk_Apps!$A$4:$A$1233)-ROW(All_Risk_Apps!$A$4)+1)/((OR(All_Risk_Apps!$D$4:$D$1233={"High","Very High"}))*(All_Risk_Apps!$K$4:$K$1233="No")*(All_Risk_Apps!$A$4:$A$1233<>"")),16)),"") | H19: =IF(B19="","",IFERROR(INDEX(Server_Inventory!$R:$R,MATCH(B19,Server_Inventory!$Z:$Z,0)),"Not Found")) | I19: =IF(B19="","",IFERROR(INDEX(Server_Inventory!$S:$S,MATCH(B19,Server_Inventory!$Z:$Z,0)),"Not Found")) | J19: =IF(B19="","",COUNTIFS(Server_Inventory!$Z:$Z,B19,Server_Inventory!$P:$P,"R-RETIRED_IN_CMDB")) | K19: =IF(B19="","",IFERROR(INDEX(Container_Inventory!$F:$F,MATCH(B19,Container_Inventory!$L:$L,0)),"Not Found")) | L19: =IF(B19="","",IF(COUNTIF(Finding_List!$A:$A,B19)>0,"Yes","No")) | M19: =IF(B19="","",COUNTIF(Server_Inventory!$Z:$Z,B19)) | N19: =IF(B19="","",COUNTIF(Container_Inventory!$L:$L,B19))
A20: =IFERROR(INDEX(All_Risk_Apps!$A$4:$A$1233,_xludf.aggregate(15,6,(ROW(All_Risk_Apps!$A$4:$A$1233)-ROW(All_Risk_Apps!$A$4)+1)/((OR(All_Risk_Apps!$D$4:$D$1233={"High","Very High"}))*(All_Risk_Apps!$K$4:$K$1233="No")*(All_Risk_Apps!$A$4:$A$1233<>"")),17)),"") | B20: =IFERROR(INDEX(All_Risk_Apps!$B$4:$B$1233,_xludf.aggregate(15,6,(ROW(All_Risk_Apps!$A$4:$A$1233)-ROW(All_Risk_Apps!$A$4)+1)/((OR(All_Risk_Apps!$D$4:$D$1233={"High","Very High"}))*(All_Risk_Apps!$K$4:$K$1233="No")*(All_Risk_Apps!$A$4:$A$1233<>"")),17)),"") | C20: =IFERROR(INDEX(All_Risk_Apps!$D$4:$D$1233,_xludf.aggregate(15,6,(ROW(All_Risk_Apps!$A$4:$A$1233)-ROW(All_Risk_Apps!$A$4)+1)/((OR(All_Risk_Apps!$D$4:$D$1233={"High","Very High"}))*(All_Risk_Apps!$K$4:$K$1233="No")*(All_Risk_Apps!$A$4:$A$1233<>"")),17)),"") | D20: =IFERROR(INDEX(All_Risk_Apps!$C$4:$C$1233,_xludf.aggregate(15,6,(ROW(All_Risk_Apps!$A$4:$A$1233)-ROW(All_Risk_Apps!$A$4)+1)/((OR(All_Risk_Apps!$D$4:$D$1233={"High","Very High"}))*(All_Risk_Apps!$K$4:$K$1233="No")*(All_Risk_Apps!$A$4:$A$1233<>"")),17)),"") | E20: =IFERROR(INDEX(All_Risk_Apps!$E$4:$E$1233,_xludf.aggregate(15,6,(ROW(All_Risk_Apps!$A$4:$A$1233)-ROW(All_Risk_Apps!$A$4)+1)/((OR(All_Risk_Apps!$D$4:$D$1233={"High","Very High"}))*(All_Risk_Apps!$K$4:$K$1233="No")*(All_Risk_Apps!$A$4:$A$1233<>"")),17)),"") | F20: =IFERROR(INDEX(All_Risk_Apps!$F$4:$F$1233,_xludf.aggregate(15,6,(ROW(All_Risk_Apps!$A$4:$A$1233)-ROW(All_Risk_Apps!$A$4)+1)/((OR(All_Risk_Apps!$D$4:$D$1233={"High","Very High"}))*(All_Risk_Apps!$K$4:$K$1233="No")*(All_Risk_Apps!$A$4:$A$1233<>"")),17)),"") | G20: =IFERROR(INDEX(All_Risk_Apps!$I$4:$I$1233,_xludf.aggregate(15,6,(ROW(All_Risk_Apps!$A$4:$A$1233)-ROW(All_Risk_Apps!$A$4)+1)/((OR(All_Risk_Apps!$D$4:$D$1233={"High","Very High"}))*(All_Risk_Apps!$K$4:$K$1233="No")*(All_Risk_Apps!$A$4:$A$1233<>"")),17)),"") | H20: =IF(B20="","",IFERROR(INDEX(Server_Inventory!$R:$R,MATCH(B20,Server_Inventory!$Z:$Z,0)),"Not Found")) | I20: =IF(B20="","",IFERROR(INDEX(Server_Inventory!$S:$S,MATCH(B20,Server_Inventory!$Z:$Z,0)),"Not Found")) | J20: =IF(B20="","",COUNTIFS(Server_Inventory!$Z:$Z,B20,Server_Inventory!$P:$P,"R-RETIRED_IN_CMDB")) | K20: =IF(B20="","",IFERROR(INDEX(Container_Inventory!$F:$F,MATCH(B20,Container_Inventory!$L:$L,0)),"Not Found")) | L20: =IF(B20="","",IF(COUNTIF(Finding_List!$A:$A,B20)>0,"Yes","No")) | M20: =IF(B20="","",COUNTIF(Server_Inventory!$Z:$Z,B20)) | N20: =IF(B20="","",COUNTIF(Container_Inventory!$L:$L,B20))
A21: =IFERROR(INDEX(All_Risk_Apps!$A$4:$A$1233,_xludf.aggregate(15,6,(ROW(All_Risk_Apps!$A$4:$A$1233)-ROW(All_Risk_Apps!$A$4)+1)/((OR(All_Risk_Apps!$D$4:$D$1233={"High","Very High"}))*(All_Risk_Apps!$K$4:$K$1233="No")*(All_Risk_Apps!$A$4:$A$1233<>"")),18)),"") | B21: =IFERROR(INDEX(All_Risk_Apps!$B$4:$B$1233,_xludf.aggregate(15,6,(ROW(All_Risk_Apps!$A$4:$A$1233)-ROW(All_Risk_Apps!$A$4)+1)/((OR(All_Risk_Apps!$D$4:$D$1233={"High","Very High"}))*(All_Risk_Apps!$K$4:$K$1233="No")*(All_Risk_Apps!$A$4:$A$1233<>"")),18)),"") | C21: =IFERROR(INDEX(All_Risk_Apps!$D$4:$D$1233,_xludf.aggregate(15,6,(ROW(All_Risk_Apps!$A$4:$A$1233)-ROW(All_Risk_Apps!$A$4)+1)/((OR(All_Risk_Apps!$D$4:$D$1233={"High","Very High"}))*(All_Risk_Apps!$K$4:$K$1233="No")*(All_Risk_Apps!$A$4:$A$1233<>"")),18)),"") | D21: =IFERROR(INDEX(All_Risk_Apps!$C$4:$C$1233,_xludf.aggregate(15,6,(ROW(All_Risk_Apps!$A$4:$A$1233)-ROW(All_Risk_Apps!$A$4)+1)/((OR(All_Risk_Apps!$D$4:$D$1233={"High","Very High"}))*(All_Risk_Apps!$K$4:$K$1233="No")*(All_Risk_Apps!$A$4:$A$1233<>"")),18)),"") | E21: =IFERROR(INDEX(All_Risk_Apps!$E$4:$E$1233,_xludf.aggregate(15,6,(ROW(All_Risk_Apps!$A$4:$A$1233)-ROW(All_Risk_Apps!$A$4)+1)/((OR(All_Risk_Apps!$D$4:$D$1233={"High","Very High"}))*(All_Risk_Apps!$K$4:$K$1233="No")*(All_Risk_Apps!$A$4:$A$1233<>"")),18)),"") | F21: =IFERROR(INDEX(All_Risk_Apps!$F$4:$F$1233,_xludf.aggregate(15,6,(ROW(All_Risk_Apps!$A$4:$A$1233)-ROW(All_Risk_Apps!$A$4)+1)/((OR(All_Risk_Apps!$D$4:$D$1233={"High","Very High"}))*(All_Risk_Apps!$K$4:$K$1233="No")*(All_Risk_Apps!$A$4:$A$1233<>"")),18)),"") | G21: =IFERROR(INDEX(All_Risk_Apps!$I$4:$I$1233,_xludf.aggregate(15,6,(ROW(All_Risk_Apps!$A$4:$A$1233)-ROW(All_Risk_Apps!$A$4)+1)/((OR(All_Risk_Apps!$D$4:$D$1233={"High","Very High"}))*(All_Risk_Apps!$K$4:$K$1233="No")*(All_Risk_Apps!$A$4:$A$1233<>"")),18)),"") | H21: =IF(B21="","",IFERROR(INDEX(Server_Inventory!$R:$R,MATCH(B21,Server_Inventory!$Z:$Z,0)),"Not Found")) | I21: =IF(B21="","",IFERROR(INDEX(Server_Inventory!$S:$S,MATCH(B21,Server_Inventory!$Z:$Z,0)),"Not Found")) | J21: =IF(B21="","",COUNTIFS(Server_Inventory!$Z:$Z,B21,Server_Inventory!$P:$P,"R-RETIRED_IN_CMDB")) | K21: =IF(B21="","",IFERROR(INDEX(Container_Inventory!$F:$F,MATCH(B21,Container_Inventory!$L:$L,0)),"Not Found")) | L21: =IF(B21="","",IF(COUNTIF(Finding_List!$A:$A,B21)>0,"Yes","No")) | M21: =IF(B21="","",COUNTIF(Server_Inventory!$Z:$Z,B21)) | N21: =IF(B21="","",COUNTIF(Container_Inventory!$L:$L,B21))
A22: =IFERROR(INDEX(All_Risk_Apps!$A$4:$A$1233,_xludf.aggregate(15,6,(ROW(All_Risk_Apps!$A$4:$A$1233)-ROW(All_Risk_Apps!$A$4)+1)/((OR(All_Risk_Apps!$D$4:$D$1233={"High","Very High"}))*(All_Risk_Apps!$K$4:$K$1233="No")*(All_Risk_Apps!$A$4:$A$1233<>"")),19)),"") | B22: =IFERROR(INDEX(All_Risk_Apps!$B$4:$B$1233,_xludf.aggregate(15,6,(ROW(All_Risk_Apps!$A$4:$A$1233)-ROW(All_Risk_Apps!$A$4)+1)/((OR(All_Risk_Apps!$D$4:$D$1233={"High","Very High"}))*(All_Risk_Apps!$K$4:$K$1233="No")*(All_Risk_Apps!$A$4:$A$1233<>"")),19)),"") | C22: =IFERROR(INDEX(All_Risk_Apps!$D$4:$D$1233,_xludf.aggregate(15,6,(ROW(All_Risk_Apps!$A$4:$A$1233)-ROW(All_Risk_Apps!$A$4)+1)/((OR(All_Risk_Apps!$D$4:$D$1233={"High","Very High"}))*(All_Risk_Apps!$K$4:$K$1233="No")*(All_Risk_Apps!$A$4:$A$1233<>"")),19)),"") | D22: =IFERROR(INDEX(All_Risk_Apps!$C$4:$C$1233,_xludf.aggregate(15,6,(ROW(All_Risk_Apps!$A$4:$A$1233)-ROW(All_Risk_Apps!$A$4)+1)/((OR(All_Risk_Apps!$D$4:$D$1233={"High","Very High"}))*(All_Risk_Apps!$K$4:$K$1233="No")*(All_Risk_Apps!$A$4:$A$1233<>"")),19)),"") | E22: =IFERROR(INDEX(All_Risk_Apps!$E$4:$E$1233,_xludf.aggregate(15,6,(ROW(All_Risk_Apps!$A$4:$A$1233)-ROW(All_Risk_Apps!$A$4)+1)/((OR(All_Risk_Apps!$D$4:$D$1233={"High","Very High"}))*(All_Risk_Apps!$K$4:$K$1233="No")*(All_Risk_Apps!$A$4:$A$1233<>"")),19)),"") | F22: =IFERROR(INDEX(All_Risk_Apps!$F$4:$F$1233,_xludf.aggregate(15,6,(ROW(All_Risk_Apps!$A$4:$A$1233)-ROW(All_Risk_Apps!$A$4)+1)/((OR(All_Risk_Apps!$D$4:$D$1233={"High","Very High"}))*(All_Risk_Apps!$K$4:$K$1233="No")*(All_Risk_Apps!$A$4:$A$1233<>"")),19)),"") | G22: =IFERROR(INDEX(All_Risk_Apps!$I$4:$I$1233,_xludf.aggregate(15,6,(ROW(All_Risk_Apps!$A$4:$A$1233)-ROW(All_Risk_Apps!$A$4)+1)/((OR(All_Risk_Apps!$D$4:$D$1233={"High","Very High"}))*(All_Risk_Apps!$K$4:$K$1233="No")*(All_Risk_Apps!$A$4:$A$1233<>"")),19)),"") | H22: =IF(B22="","",IFERROR(INDEX(Server_Inventory!$R:$R,MATCH(B22,Server_Inventory!$Z:$Z,0)),"Not Found")) | I22: =IF(B22="","",IFERROR(INDEX(Server_Inventory!$S:$S,MATCH(B22,Server_Inventory!$Z:$Z,0)),"Not Found")) | J22: =IF(B22="","",COUNTIFS(Server_Inventory!$Z:$Z,B22,Server_Inventory!$P:$P,"R-RETIRED_IN_CMDB")) | K22: =IF(B22="","",IFERROR(INDEX(Container_Inventory!$F:$F,MATCH(B22,Container_Inventory!$L:$L,0)),"Not Found")) | L22: =IF(B22="","",IF(COUNTIF(Finding_List!$A:$A,B22)>0,"Yes","No")) | M22: =IF(B22="","",COUNTIF(Server_Inventory!$Z:$Z,B22)) | N22: =IF(B22="","",COUNTIF(Container_Inventory!$L:$L,B22))
A23: =IFERROR(INDEX(All_Risk_Apps!$A$4:$A$1233,_xludf.aggregate(15,6,(ROW(All_Risk_Apps!$A$4:$A$1233)-ROW(All_Risk_Apps!$A$4)+1)/((OR(All_Risk_Apps!$D$4:$D$1233={"High","Very High"}))*(All_Risk_Apps!$K$4:$K$1233="No")*(All_Risk_Apps!$A$4:$A$1233<>"")),20)),"") | B23: =IFERROR(INDEX(All_Risk_Apps!$B$4:$B$1233,_xludf.aggregate(15,6,(ROW(All_Risk_Apps!$A$4:$A$1233)-ROW(All_Risk_Apps!$A$4)+1)/((OR(All_Risk_Apps!$D$4:$D$1233={"High","Very High"}))*(All_Risk_Apps!$K$4:$K$1233="No")*(All_Risk_Apps!$A$4:$A$1233<>"")),20)),"") | C23: =IFERROR(INDEX(All_Risk_Apps!$D$4:$D$1233,_xludf.aggregate(15,6,(ROW(All_Risk_Apps!$A$4:$A$1233)-ROW(All_Risk_Apps!$A$4)+1)/((OR(All_Risk_Apps!$D$4:$D$1233={"High","Very High"}))*(All_Risk_Apps!$K$4:$K$1233="No")*(All_Risk_Apps!$A$4:$A$1233<>"")),20)),"") | D23: =IFERROR(INDEX(All_Risk_Apps!$C$4:$C$1233,_xludf.aggregate(15,6,(ROW(All_Risk_Apps!$A$4:$A$1233)-ROW(All_Risk_Apps!$A$4)+1)/((OR(All_Risk_Apps!$D$4:$D$1233={"High","Very High"}))*(All_Risk_Apps!$K$4:$K$1233="No")*(All_Risk_Apps!$A$4:$A$1233<>"")),20)),"") | E23: =IFERROR(INDEX(All_Risk_Apps!$E$4:$E$1233,_xludf.aggregate(15,6,(ROW(All_Risk_Apps!$A$4:$A$1233)-ROW(All_Risk_Apps!$A$4)+1)/((OR(All_Risk_Apps!$D$4:$D$1233={"High","Very High"}))*(All_Risk_Apps!$K$4:$K$1233="No")*(All_Risk_Apps!$A$4:$A$1233<>"")),20)),"") | F23: =IFERROR(INDEX(All_Risk_Apps!$F$4:$F$1233,_xludf.aggregate(15,6,(ROW(All_Risk_Apps!$A$4:$A$1233)-ROW(All_Risk_Apps!$A$4)+1)/((OR(All_Risk_Apps!$D$4:$D$1233={"High","Very High"}))*(All_Risk_Apps!$K$4:$K$1233="No")*(All_Risk_Apps!$A$4:$A$1233<>"")),20)),"") | G23: =IFERROR(INDEX(All_Risk_Apps!$I$4:$I$1233,_xludf.aggregate(15,6,(ROW(All_Risk_Apps!$A$4:$A$1233)-ROW(All_Risk_Apps!$A$4)+1)/((OR(All_Risk_Apps!$D$4:$D$1233={"High","Very High"}))*(All_Risk_Apps!$K$4:$K$1233="No")*(All_Risk_Apps!$A$4:$A$1233<>"")),20)),"") | H23: =IF(B23="","",IFERROR(INDEX(Server_Inventory!$R:$R,MATCH(B23,Server_Inventory!$Z:$Z,0)),"Not Found")) | I23: =IF(B23="","",IFERROR(INDEX(Server_Inventory!$S:$S,MATCH(B23,Server_Inventory!$Z:$Z,0)),"Not Found")) | J23: =IF(B23="","",COUNTIFS(Server_Inventory!$Z:$Z,B23,Server_Inventory!$P:$P,"R-RETIRED_IN_CMDB")) | K23: =IF(B23="","",IFERROR(INDEX(Container_Inventory!$F:$F,MATCH(B23,Container_Inventory!$L:$L,0)),"Not Found")) | L23: =IF(B23="","",IF(COUNTIF(Finding_List!$A:$A,B23)>0,"Yes","No")) | M23: =IF(B23="","",COUNTIF(Server_Inventory!$Z:$Z,B23)) | N23: =IF(B23="","",COUNTIF(Container_Inventory!$L:$L,B23))
A24: =IFERROR(INDEX(All_Risk_Apps!$A$4:$A$1233,_xludf.aggregate(15,6,(ROW(All_Risk_Apps!$A$4:$A$1233)-ROW(All_Risk_Apps!$A$4)+1)/((OR(All_Risk_Apps!$D$4:$D$1233={"High","Very High"}))*(All_Risk_Apps!$K$4:$K$1233="No")*(All_Risk_Apps!$A$4:$A$1233<>"")),21)),"") | B24: =IFERROR(INDEX(All_Risk_Apps!$B$4:$B$1233,_xludf.aggregate(15,6,(ROW(All_Risk_Apps!$A$4:$A$1233)-ROW(All_Risk_Apps!$A$4)+1)/((OR(All_Risk_Apps!$D$4:$D$1233={"High","Very High"}))*(All_Risk_Apps!$K$4:$K$1233="No")*(All_Risk_Apps!$A$4:$A$1233<>"")),21)),"") | C24: =IFERROR(INDEX(All_Risk_Apps!$D$4:$D$1233,_xludf.aggregate(15,6,(ROW(All_Risk_Apps!$A$4:$A$1233)-ROW(All_Risk_Apps!$A$4)+1)/((OR(All_Risk_Apps!$D$4:$D$1233={"High","Very High"}))*(All_Risk_Apps!$K$4:$K$1233="No")*(All_Risk_Apps!$A$4:$A$1233<>"")),21)),"") | D24: =IFERROR(INDEX(All_Risk_Apps!$C$4:$C$1233,_xludf.aggregate(15,6,(ROW(All_Risk_Apps!$A$4:$A$1233)-ROW(All_Risk_Apps!$A$4)+1)/((OR(All_Risk_Apps!$D$4:$D$1233={"High","Very High"}))*(All_Risk_Apps!$K$4:$K$1233="No")*(All_Risk_Apps!$A$4:$A$1233<>"")),21)),"") | E24: =IFERROR(INDEX(All_Risk_Apps!$E$4:$E$1233,_xludf.aggregate(15,6,(ROW(All_Risk_Apps!$A$4:$A$1233)-ROW(All_Risk_Apps!$A$4)+1)/((OR(All_Risk_Apps!$D$4:$D$1233={"High","Very High"}))*(All_Risk_Apps!$K$4:$K$1233="No")*(All_Risk_Apps!$A$4:$A$1233<>"")),21)),"") | F24: =IFERROR(INDEX(All_Risk_Apps!$F$4:$F$1233,_xludf.aggregate(15,6,(ROW(All_Risk_Apps!$A$4:$A$1233)-ROW(All_Risk_Apps!$A$4)+1)/((OR(All_Risk_Apps!$D$4:$D$1233={"High","Very High"}))*(All_Risk_Apps!$K$4:$K$1233="No")*(All_Risk_Apps!$A$4:$A$1233<>"")),21)),"") | G24: =IFERROR(INDEX(All_Risk_Apps!$I$4:$I$1233,_xludf.aggregate(15,6,(ROW(All_Risk_Apps!$A$4:$A$1233)-ROW(All_Risk_Apps!$A$4)+1)/((OR(All_Risk_Apps!$D$4:$D$1233={"High","Very High"}))*(All_Risk_Apps!$K$4:$K$1233="No")*(All_Risk_Apps!$A$4:$A$1233<>"")),21)),"") | H24: =IF(B24="","",IFERROR(INDEX(Server_Inventory!$R:$R,MATCH(B24,Server_Inventory!$Z:$Z,0)),"Not Found")) | I24: =IF(B24="","",IFERROR(INDEX(Server_Inventory!$S:$S,MATCH(B24,Server_Inventory!$Z:$Z,0)),"Not Found")) | J24: =IF(B24="","",COUNTIFS(Server_Inventory!$Z:$Z,B24,Server_Inventory!$P:$P,"R-RETIRED_IN_CMDB")) | K24: =IF(B24="","",IFERROR(INDEX(Container_Inventory!$F:$F,MATCH(B24,Container_Inventory!$L:$L,0)),"Not Found")) | L24: =IF(B24="","",IF(COUNTIF(Finding_List!$A:$A,B24)>0,"Yes","No")) | M24: =IF(B24="","",COUNTIF(Server_Inventory!$Z:$Z,B24)) | N24: =IF(B24="","",COUNTIF(Container_Inventory!$L:$L,B24))
